<?xml version="1.0" ?>
<!-- =================================================================================== -->
<!-- |    This document was autogenerated by xacro from igt_one.xacro                  | -->
<!-- |    EDITING THIS FILE BY HAND IS NOT RECOMMENDED                                 | -->
<!-- =================================================================================== -->
<robot name="igt_one">
  <!-- <material name="silver">
    <color rgba="0.700 0.700 0.700 1.000"/>
  </material> -->

  <transmission name="front_right_motor_tran">
    <type>transmission_interface/SimpleTransmission</type>
    <joint name="front_right_motor">
      <hardwareInterface>hardware_interface/EffortJointInterface</hardwareInterface>
    </joint>
    <actuator name="front_right_motor_actr">
      <hardwareInterface>hardware_interface/EffortJointInterface</hardwareInterface>
      <mechanicalReduction>1</mechanicalReduction>
    </actuator>
  </transmission>

  <transmission name="front_left_motor_tran">
    <type>transmission_interface/SimpleTransmission</type>
    <joint name="front_left_motor">
      <hardwareInterface>hardware_interface/EffortJointInterface</hardwareInterface>
    </joint>
    <actuator name="front_left_motor_actr">
      <hardwareInterface>hardware_interface/EffortJointInterface</hardwareInterface>
      <mechanicalReduction>1</mechanicalReduction>
    </actuator>
  </transmission>

  <transmission name="rear_right_motor_tran">
    <type>transmission_interface/SimpleTransmission</type>
    <joint name="rear_right_motor">
      <hardwareInterface>hardware_interface/EffortJointInterface</hardwareInterface>
    </joint>
    <actuator name="rear_right_motor_actr">
      <hardwareInterface>hardware_interface/EffortJointInterface</hardwareInterface>
      <mechanicalReduction>1</mechanicalReduction>
    </actuator>
  </transmission>

  <transmission name="rear_left_motor_tran">
    <type>transmission_interface/SimpleTransmission</type>
    <joint name="rear_left_motor">
      <hardwareInterface>hardware_interface/EffortJointInterface</hardwareInterface>
    </joint>
    <actuator name="rear_left_motor_actr">
      <hardwareInterface>hardware_interface/EffortJointInterface</hardwareInterface>
      <mechanicalReduction>1</mechanicalReduction>
    </actuator>
  </transmission>

  <!-- <gazebo reference="base_link">
    <material>Gazebo/Silver</material>
  </gazebo>
  <gazebo reference="right_wheel">
    <material>Gazebo/DarkGrey</material>
  </gazebo>
  <gazebo reference="left_wheel">
    <material>Gazebo/DarkGrey</material>
  </gazebo>
  <gazebo reference="lidar">
    <material>Gazebo/Black</material>
  </gazebo>
  <gazebo reference="caster_front">
    <material>Gazebo/DarkGrey</material>
  </gazebo>
  <gazebo reference="caster_back">
    <material>Gazebo/DarkGrey</material>
  </gazebo> -->

  <gazebo reference="base_link">
    <mu1>1.0</mu1>
    <mu2>1.0</mu2>
    <selfCollide>true</selfCollide>
    <gravity>true</gravity>
  </gazebo>

  <gazebo reference="front_right_wheel">
    <mu1>500.0</mu1>
    <mu2>500.0</mu2>
    <selfCollide>true</selfCollide>
  </gazebo>

  <gazebo reference="front_left_wheel">
    <mu1>500.0</mu1>
    <mu2>500.0</mu2>
    <selfCollide>true</selfCollide>
  </gazebo>

  <gazebo reference="rear_right_wheel">
    <mu1>500.0</mu1>
    <mu2>500.0</mu2>
    <selfCollide>true</selfCollide>
  </gazebo>

  <gazebo reference="rear_left_wheel">
    <mu1>500.0</mu1>
    <mu2>500.0</mu2>
    <selfCollide>true</selfCollide>
  </gazebo>

  <gazebo reference="lidar">
    <mu1>1.0</mu1>
    <mu2>1.0</mu2>
    <selfCollide>true</selfCollide>
  </gazebo>

  <!-- <gazebo reference="caster_front">
    <mu1>0.01</mu1>
    <mu2>0.01</mu2>
    <selfCollide>true</selfCollide>
  </gazebo>
  <gazebo reference="caster_back">
    <mu1>0.01</mu1>
    <mu2>0.01</mu2>
    <selfCollide>true</selfCollide>
  </gazebo> -->

  <gazebo>
    <plugin filename="libgazebo_ros_control.so" name="gazebo_ros_control">
      <robotNamespace>/igt_one</robotNamespace>
      <robotSimType>gazebo_ros_control/DefaultRobotHWSim</robotSimType>
      <legacyModeNS>true</legacyModeNS>
    </plugin>
  </gazebo>

  <gazebo>
    <plugin filename="libgazebo_ros_diff_drive.so" name="differential_drive_controller">
      <legacyMode>false</legacyMode>
      <num_wheel_pairs>2</num_wheel_pairs>
      <alwaysOn>true</alwaysOn>
      <updateRate>100</updateRate>
      <leftJoint>front_left_motor</leftJoint>
      <rightJoint>front_right_motor</rightJoint>
      <leftJoint>rear_left_motor</leftJoint>
      <rightJoint>rear_right_motor</rightJoint>
      <commandTopic>cmd_vel</commandTopic>
      <odometryTopic>odom</odometryTopic>
      <odometryFrame>odom</odometryFrame>
      <robotBaseFrame>base_link</robotBaseFrame>
    </plugin>
  </gazebo>

  <gazebo reference="lidar">
    <sensor name="front_lidar" type="ray">
      <pose>0 0 0 0 0 0</pose>
      <visualize>False</visualize>
      <update_rate>100</update_rate>
      <ray>
        <scan>
          <horizontal>
            <samples>720</samples>
            <resolution>1</resolution>
            <min_angle>-1.8326</min_angle>
            <max_angle>1.8326</max_angle>
          </horizontal>
        </scan>
        <range>
          <min>0.05</min>
          <max>20.0</max>
          <resolution>0.01</resolution>
        </range>
        <noise>
          <type>gaussian</type>
          <mean>0.0</mean>
          <stddev>0.01</stddev>
        </noise>
      </ray>
      <plugin filename="libgazebo_ros_laser.so" name="gazebo_ros_head_hokuyo_controller">
        <topicName>/igt_one/laserscan</topicName>
        <frameName>lidar</frameName>
      </plugin>
    </sensor>
  </gazebo> 

  <link name="base_link">
    <inertial>
      <origin rpy="0 0 0" xyz="0 0 0.062329"/>
      <mass value="46.064"/>
      <inertia ixx="0.615397" ixy="-0.0240585" ixz="-0.1207498" iyy="1.75388" iyz="-0.0028322" izz="2.03641"/>
    </inertial>
    <visual>
      <origin rpy="0 0 0" xyz="0 0 0"/>
      <geometry>
        <mesh filename="file:///home/jasonwoo/colcon_ws/src/ros2-igt/igt_ignition/igt_one/meshes/top_chassis.dae" scale="1 1 1"/>
      </geometry>
    </visual>
    <collision>
      <origin rpy="0 0 0" xyz="0 0 0.12"/>
      <geometry>
        <mesh filename="file:///home/jasonwoo/colcon_ws/src/ros2-igt/igt_ignition/igt_one/meshes/top_chassis.dae" scale="0.9874 0.5709 0.05"/>
      </geometry>
    </collision>
  </link>

  <link name="front_left_wheel">
    <inertial>
      <origin rpy="0 0 0" xyz="0 0 0"/>
      <mass value="2.637"/>
      <inertia ixx="0.02467" ixy="0.0" ixz="0.0" iyy="0.04411" iyz="0.0" izz="0.02467"/>
    </inertial>
    <visual>
      <origin rpy="0 0 0" xyz="0 0 0"/>
      <geometry>
        <mesh filename="file:///home/jasonwoo/colcon_ws/src/ros2-igt/igt_ignition/igt_one/meshes/wheel.dae" scale="1 1 1"/>
      </geometry>
    </visual>
    <collision>
      <origin rpy="1.5707963267948966 0 0" xyz="0 0 0"/>
      <geometry>
        <mesh filename="file:///home/jasonwoo/colcon_ws/src/ros2-igt/igt_ignition/igt_one/meshes/wheel.dae" scale="1 1 1"/>
      </geometry>
    </collision>
  </link>

  <link name="front_right_wheel">
    <inertial>
      <origin rpy="0 0 0" xyz="0 0 0"/>
      <mass value="2.637"/>
      <inertia ixx="0.02467" ixy="0.0" ixz="0.0" iyy="0.04411" iyz="0.0" izz="0.02467"/>
    </inertial>
    <visual>
      <origin rpy="0 0 0" xyz="0 0 0"/>
      <geometry>
        <mesh filename="file:///home/jasonwoo/colcon_ws/src/ros2-igt/igt_ignition/igt_one/meshes/wheel.dae" scale="1 1 1"/>
      </geometry>
    </visual>
    <collision>
      <origin rpy="1.5707963267948966 0 0" xyz="0 0 0"/>
      <geometry>
        <mesh filename="file:///home/jasonwoo/colcon_ws/src/ros2-igt/igt_ignition/igt_one/meshes/wheel.dae" scale="1 1 1"/>
      </geometry>
    </collision>
  </link>

  <link name="rear_right_wheel">
    <inertial>
      <origin rpy="0 0 0" xyz="0 0 0"/>
      <mass value="2.637"/>
      <inertia ixx="0.02467" ixy="0.0" ixz="0.0" iyy="0.04411" iyz="0.0" izz="0.02467"/>
    </inertial>
    <visual>
      <origin rpy="0 0 0" xyz="0 0 0"/>
      <geometry>
        <mesh filename="file:///home/jasonwoo/colcon_ws/src/ros2-igt/igt_ignition/igt_one/meshes/wheel.dae" scale="1 1 1"/>
      </geometry>
    </visual>
    <collision>
      <origin rpy="1.5707963267948966 0 0" xyz="0 0 0"/>
      <geometry>
        <mesh filename="file:///home/jasonwoo/colcon_ws/src/ros2-igt/igt_ignition/igt_one/meshes/wheel.dae" scale="1 1 1"/>
      </geometry>
    </collision>
  </link>

  <link name="rear_left_wheel">
    <inertial>
      <origin rpy="0 0 0" xyz="0 0 0"/>
      <mass value="2.637"/>
      <inertia ixx="0.02467" ixy="0.0" ixz="0.0" iyy="0.04411" iyz="0.0" izz="0.02467"/>
    </inertial>
    <visual>
      <origin rpy="0 0 0" xyz="0 0 0"/>
      <geometry>
        <mesh filename="file:///home/jasonwoo/colcon_ws/src/ros2-igt/igt_ignition/igt_one/meshes/wheel.dae" scale="1 1 1"/>
      </geometry>
    </visual>
    <collision>
      <origin rpy="1.5707963267948966 0 0" xyz="0 0 0"/>
      <geometry>
        <mesh filename="file:///home/jasonwoo/colcon_ws/src/ros2-igt/igt_ignition/igt_one/meshes/wheel.dae" scale="1 1 1"/>
      </geometry>
    </collision>
  </link>

  <link name="lidar">
    <inertial>
      <origin rpy="0 0 0" xyz="7.078254841363929e-06 -5.464739684171491e-06 -0.005199589249268707"/>
      <mass value="0.4698523118913531"/>
      <inertia ixx="0.000216" ixy="-0.0" ixz="0.0" iyy="0.000216" iyz="-0.0" izz="0.000424"/>
    </inertial>
    <visual>
      <origin rpy="0 0 0" xyz="-0.278738 -3e-06 -0.044475"/>
      <geometry>
        <mesh filename="package://igt_ignition/models/igt_one/meshes/lidar.stl" scale="0.001 0.001 0.001"/>
      </geometry>
    </visual>
    <collision>
      <origin rpy="0 0 0" xyz="-0.278738 -3e-06 -0.044475"/>
      <geometry>
        <mesh filename="package://igt_ignition/models/igt_one/meshes/lidar.stl" scale="0.001 0.001 0.001"/>
      </geometry>
    </collision>
  </link>

  <!-- camera body, with origin at bottom screw mount -->
  <joint name="d435_joint" type="fixed">
    <origin rpy="0 0 0 " xyz="0 0 .5"/>
    <parent link="base_link"/>
    <child link="d435_bottom_screw_frame"/>
  </joint>

  <link name="d435_bottom_screw_frame"/>

  <joint name="d435_link_joint" type="fixed">
    <origin rpy="0 0 0" xyz="0 0.0175 0.0125"/>
    <parent link="d435_bottom_screw_frame"/>
    <child link="d435_link"/>
  </joint>

  <link name="d435_link">
    <visual>
      <origin rpy="1.5707963267948966 0 1.5707963267948966" xyz="0.0149 -0.0175 0"/>
      <geometry>
        <mesh filename="package://igt_ignition/models/igt_one/meshes/realsense_d435.stl"/>
      </geometry>
    </visual>
    <collision>
      <origin rpy="0 0 0" xyz="0 -0.0175 0"/>
      <geometry>
        <box size="0.02505 0.09 0.025"/>
      </geometry>
    </collision>
    <inertial>
      <mass value="0.564"/>
      <origin rpy="0 0 0" xyz="0 -0.0175 0"/>
      <inertia ixx="0.000410075" ixy="0" ixz="0" iyy="5.8867617499999996e-05" iyz="0" izz="5.8867617499999996e-05"/>
    </inertial>
  </link>

  <!-- camera depth joints and links -->
  <joint name="d435_depth_joint" type="fixed">
    <origin rpy="0 0 0" xyz="0 0 0"/>
    <parent link="d435_link"/>
    <child link="d435_depth_frame"/>
  </joint>

  <link name="d435_depth_frame"/>

  <joint name="d435_depth_optical_joint" type="fixed">
    <origin rpy="-1.5707963267948966 0 -1.5707963267948966" xyz="0 0 0"/>
    <parent link="d435_depth_frame"/>
    <child link="d435_depth_optical_frame"/>
  </joint>

  <link name="d435_depth_optical_frame"/>

  <!-- camera left IR joints and links -->
  <joint name="d435_left_ir_joint" type="fixed">
    <origin rpy="0 0 0" xyz="0 0.0 0"/>
    <parent link="d435_depth_frame"/>
    <child link="d435_left_ir_frame"/>
  </joint>

  <link name="d435_left_ir_frame"/>

  <joint name="d435_left_ir_optical_joint" type="fixed">
    <origin rpy="-1.5707963267948966 0 -1.5707963267948966" xyz="0 0 0"/>
    <parent link="d435_left_ir_frame"/>
    <child link="d435_left_ir_optical_frame"/>
  </joint>

  <link name="d435_left_ir_optical_frame"/>

  <!-- camera right IR joints and links -->
  <joint name="d435_right_ir_joint" type="fixed">
    <origin rpy="0 0 0" xyz="0 -0.05 0"/>
    <parent link="d435_depth_frame"/>
    <child link="d435_right_ir_frame"/>
  </joint>

  <link name="d435_right_ir_frame"/>

  <joint name="d435_right_ir_optical_joint" type="fixed">
    <origin rpy="-1.5707963267948966 0 -1.5707963267948966" xyz="0 0 0"/>
    <parent link="d435_right_ir_frame"/>
    <child link="d435_right_ir_optical_frame"/>
  </joint>

  <link name="d435_right_ir_optical_frame"/>

  <!-- camera color joints and links -->
  <joint name="d435_color_joint" type="fixed">
    <origin rpy="0 0 0" xyz="0 0.015 0"/>
    <parent link="d435_depth_frame"/>
    <child link="d435_color_frame"/>
  </joint>

  <link name="d435_color_frame"/>

  <joint name="d435_color_optical_joint" type="fixed">
    <origin rpy="-1.5707963267948966 0 -1.5707963267948966" xyz="0 0 0"/>
    <parent link="d435_color_frame"/>
    <child link="d435_color_optical_frame"/>
  </joint>

  <link name="d435_color_optical_frame"/>

  <!-- gazebo plugin -->
  <gazebo reference="d435_link">
    <self_collide>0</self_collide>
    <enable_wind>0</enable_wind>
    <kinematic>0</kinematic>
    <gravity>1</gravity>
    <mu2>1</mu2>
    <fdir1>0 0 0</fdir1>
    <kp>1e+13</kp>
    <kd>1</kd>
    <sensor name="d435_color" type="camera">
      <camera name="d435">
        <horizontal_fov>1.2112585008840648</horizontal_fov>
        <image>
          <width>640</width>
          <height>480</height>
          <format>RGB_INT8</format>
        </image>
        <clip>
          <near>0.1</near>
          <far>100</far>
        </clip>
        <noise>
          <type>gaussian</type>
          <mean>0.0</mean>
          <stddev>0.007</stddev>
        </noise>
      </camera>
      <always_on>1</always_on>
      <update_rate>30</update_rate>
      <visualize>1</visualize>
    </sensor>
    <sensor name="d435_ired1" type="camera">
      <camera name="d435">
        <horizontal_fov>1.4870205226991688</horizontal_fov>
        <image>
          <width>1280</width>
          <height>720</height>
          <format>L_INT8</format>
        </image>
        <clip>
          <near>0.1</near>
          <far>100</far>
        </clip>
        <noise>
          <type>gaussian</type>
          <mean>0.0</mean>
          <stddev>0.05</stddev>
        </noise>
      </camera>
      <always_on>1</always_on>
      <update_rate>90</update_rate>
      <visualize>0</visualize>
    </sensor>
    <sensor name="d435_ired2" type="camera">
      <camera name="d435">
        <horizontal_fov>1.4870205226991688</horizontal_fov>
        <image>
          <width>1280</width>
          <height>720</height>
          <format>L_INT8</format>
        </image>
        <clip>
          <near>0.1</near>
          <far>100</far>
        </clip>
        <noise>
          <type>gaussian</type>
          <mean>0.0</mean>
          <stddev>0.05</stddev>
        </noise>
      </camera>
      <always_on>1</always_on>
      <update_rate>90</update_rate>
      <visualize>0</visualize>
    </sensor>
    <sensor name="d435_depth" type="depth">
      <camera name="d435">
        <horizontal_fov>1.4870205226991688</horizontal_fov>
        <image>
          <width>1280</width>
          <height>720</height>
        </image>
        <clip>
          <near>0.1</near>
          <far>100</far>
        </clip>
        <noise>
          <type>gaussian</type>
          <mean>0.0</mean>
          <stddev>0.100</stddev>
        </noise>
      </camera>
      <always_on>1</always_on>
      <update_rate>90</update_rate>
      <visualize>0</visualize>
    </sensor>
  </gazebo>

  <gazebo>
    <plugin filename="librealsense_gazebo_plugin.so" name="d435">
      <prefix>d435_</prefix>
      <depthUpdateRate>10</depthUpdateRate>
      <colorUpdateRate>10</colorUpdateRate>
      <infraredUpdateRate>10</infraredUpdateRate>
      <depthTopicName>depth/image_raw</depthTopicName>
      <depthCameraInfoTopicName>depth/camera_info</depthCameraInfoTopicName>
      <colorTopicName>color/image_raw</colorTopicName>
      <colorCameraInfoTopicName>color/camera_info</colorCameraInfoTopicName>
      <infrared1TopicName>infra1/image_raw</infrared1TopicName>
      <infrared1CameraInfoTopicName>infra1/camera_info</infrared1CameraInfoTopicName>
      <infrared2TopicName>infra2/image_raw</infrared2TopicName>
      <infrared2CameraInfoTopicName>infra2/camera_info</infrared2CameraInfoTopicName>
      <colorOpticalframeName>d435_color_optical_frame</colorOpticalframeName>
      <depthOpticalframeName>d435_depth_optical_frame</depthOpticalframeName>
      <infrared1OpticalframeName>d435_infrared1_optical_frame</infrared1OpticalframeName>
      <infrared2OpticalframeName>d435_infrared2_optical_frame</infrared2OpticalframeName>
      <rangeMinDepth>0.2</rangeMinDepth>
      <rangeMaxDepth>10.0</rangeMaxDepth>
      <pointCloud>false</pointCloud>
      <pointCloudTopicName>depth/color/points</pointCloudTopicName>
      <pointCloudCutoff>0.25</pointCloudCutoff>
      <pointCloudCutoffMax>9.0</pointCloudCutoffMax>
    </plugin>
  </gazebo>

  <joint name="front_right_motor" type="continuous">
    <parent link="base_link"/>
    <child link="front_right_wheel"/>
    <axis xyz="-0.0 1 -0.0"/>
  </joint>

  <joint name="front_left_motor" type="continuous">
    <parent link="base_link"/>
    <child link="front_left_wheel"/>
    <axis xyz="-0.0 1 -0.0"/>
  </joint>

  <joint name="Rigid3" type="fixed">
    <origin rpy="0 0 0" xyz="0.278738 0 0.2475"/>
    <parent link="base_link"/>
    <child link="lidar"/>
  </joint>

  <joint name="rear_left_motor" type="continuous">
    <parent link="base_link"/>
    <child link="rear_left_wheel"/>
    <axis xyz="-0.0 1 -0.0"/>
  </joint>

  <joint name="rear_right_motor" type="continuous">
    <parent link="base_link"/>
    <child link="rear_right_wheel"/>
    <axis xyz="-0.0 1 -0.0"/>
  </joint>
</robot>
